<?xml version="1.0"?>
 <robot name="allbot_4" xmlns:xacro="http://ros.org/wiki/xacro">
  <xacro:include filename="$(find allbot_urdf)/urdf/common_properties.xacro"/>
  <!-- <xacro:include filename="$(find allbot_urdf)/urdf/allbot.gazebo.xacro"/> -->
  <link name="base_footprint"/>

  <joint name="base_joint" type="fixed">
    <parent link="base_footprint"/>
    <child link="base_link"/>
    <origin xyz="0.0 0.0 0.010" rpy="0 0 0"/>
  </joint>

  <link name="base_link">
    <visual>
      <geometry>
        <box size="0.23 0.15 0.005"/>
      </geometry>
      <origin rpy="0 0 0" xyz="0 0 0.065"/>
      <material name="blue"/>
    </visual>
  </link>

  <link name="base_link_head">
    <visual>
      <geometry>
        <cylinder length="0.005" radius="0.075"/>
      </geometry>
      <origin rpy="0 0 0" xyz="0.11 0 0.065"/>
      <material name="blue"/>
    </visual>
  </link>

    <link name="perception_deck">
      <visual>
        <geometry>
          <box size="0.23 0.15 0.005"/>
        </geometry>
        <origin rpy="0 0 0" xyz="0 0 0.12"/>
        <material name="blue"/>
      </visual>
    </link>

    <link name="perception_deck_head">
      <visual>
        <geometry>
          <cylinder length="0.005" radius="0.075"/>
        </geometry>
        <origin rpy="0 0 0" xyz="0.11 0 0.12"/>
        <material name="blue"/>
      </visual>
    </link>

    <link name="lidar_deck">  <!-- jay -->
      <visual>
        <geometry>
          <box size="0.23 0.15 0.005"/>
        </geometry>
        <origin rpy="0 0 0" xyz="0 0 0.17"/>
        <material name="blue"/>
      </visual>
    </link>

    <link name="lidar_deck_head">
      <visual>
        <geometry>
          <cylinder length="0.005" radius="0.075"/>
        </geometry>
        <origin rpy="0 0 0" xyz="0.11 0 0.17"/>
        <material name="blue"/>
      </visual>
    </link>

    <link name="wheel_rear_left">
      <visual>
        <geometry>
          <cylinder length="0.027" radius="0.0345"/>
        </geometry>
        <origin rpy="1.57 0 0" xyz="-0.085 0.11 0.0345"/>
        <material name="black"/>
      </visual>
    </link>

    <link name="wheel_rear_right">
      <visual>
        <geometry>
          <cylinder length="0.027" radius="0.0345"/>
        </geometry>
        <origin rpy="1.57 0 0" xyz="-0.085 -0.11 0.0345"/>
        <material name="black"/>
      </visual>
    </link>

    <link name="wheel_front_left"> 
      <visual>
        <geometry>
          <cylinder length="0.027" radius="0.0345"/>
        </geometry>
        <origin rpy="1.57 0 0" xyz="0.085 -0.11 0.0345"/>
        <material name="black"/>
      </visual>
    </link>

    <link name="wheel_front_right">
      <visual>
        <geometry>
          <cylinder length="0.027" radius="0.0345"/>
        </geometry>
        <origin rpy="1.57 0 0" xyz="0.085 0.11 0.0345"/>
        <material name="black"/>
      </visual>
    </link>

    <link name="wheel_rear_track">
      <visual>
        <geometry>
          <box size="0.04 0.19 0.002"/>
        </geometry>
        <origin rpy="0 0 0" xyz="-0.085 0.0 0.06"/>
        <material name="white"/>
      </visual>
    </link>

    <link name="wheel_front_track"> 
      <visual>
        <geometry>
          <box size="0.04 0.19 0.002"/>
        </geometry>
        <origin rpy="0 0 0" xyz="0.085 0.0 0.06"/>
        <material name="white"/>
      </visual>
    </link>

    <link name="lidar">
      <visual>
        <origin rpy="0 0 0.0" xyz="0 0 0"/>
        <geometry>
         <cylinder length="0.04" radius="0.04"/>
        <!-- <mesh filename="package://allbot_urdf/urdf/lds.stl" scale="0.001 0.001 0.001"/> -->
        </geometry>
        <material name="dark"/>
      </visual>
    </link>
    
    <link name="left_rear_pole">
      <visual>
        <geometry>
          <box size="0.01 0.01 0.095"/>
        </geometry>
        <origin rpy="0 0 0" xyz="-0.10 0.055 0.1175"/>
        <material name="silver"/>
      </visual>
    </link>

    <link name="left_front_pole">
      <visual>
        <geometry>
          <box size="0.01 0.01 0.095"/>
        </geometry>
        <origin rpy="0 0 0" xyz="0.13 0.055 0.1175"/>
        <material name="silver"/>
      </visual>
    </link>

    <link name="right_rear_pole">
      <visual>
        <geometry>
          <box size="0.01 0.01 0.095"/>
        </geometry>
        <origin rpy="0 0 0" xyz="-0.10 -0.055 0.1175"/>
        <material name="silver"/>
      </visual>
    </link>

    <link name="right_front_pole">
      <visual>
        <geometry>
          <box size="0.01 0.01 0.095"/>
        </geometry>
        <origin rpy="0 0 0" xyz="0.13 -0.055 0.1175"/>
        <material name="silver"/>
      </visual>
    </link>

    <joint name="base_to_base_link_head" type="fixed">
      <parent link="base_link"/>
      <child link="base_link_head"/>
      <origin xyz="0 0 0"/>
    </joint>

    <joint name="base_to_lidar_deck" type="fixed">
      <parent link="base_link"/>
      <child link="lidar_deck"/>
      <origin xyz="0 0 0"/>
    </joint>

    <joint name="base_to_lidar_deck_head" type="fixed">
      <parent link="base_link"/>
      <child link="lidar_deck_head"/>
      <origin xyz="0 0 0"/>
    </joint>

    <joint name="base_to_wheel_front_left" type="continuous">
      <parent link="base_link"/>
      <child link="wheel_front_left"/>
      <origin xyz="0 0 0"/>
    </joint>

    <joint name="base_to_wheel_front_right" type="continuous">
      <parent link="base_link"/>
      <child link="wheel_front_right"/>
      <origin xyz="0 0 0"/>
    </joint>

    <joint name="base_to_wheel_rear_left" type="continuous">
      <parent link="base_link"/>
      <child link="wheel_rear_left"/>
      <origin xyz="0 0 0"/>
    </joint>

    <joint name="base_to_wheel_rear_right" type="continuous">
      <parent link="base_link"/>
      <child link="wheel_rear_right"/>
      <origin xyz="0 0 0"/>
    </joint>

    <joint name="base_to_wheel_front_track" type="fixed">
      <parent link="base_link"/>
      <child link="wheel_front_track"/>
      <origin xyz="0 0 0"/>
    </joint>

    <joint name="base_to_wheel_rear_track" type="fixed">
      <parent link="base_link"/>
      <child link="wheel_rear_track"/>
      <origin xyz="0 0 0"/>
    </joint>

    <joint name="base_to_laser" type="fixed">
      <parent link="base_link"/>
      <child link="lidar"/>
      <origin xyz="0.0 0.0 0.1960"/>      
    </joint>

    <joint name="base_to_left_pole_one" type="fixed">
      <parent link="base_link"/>
      <child link="left_rear_pole"/>
      <origin xyz="0 0 0"/>
    </joint>

    <joint name="base_to_left_pole_two" type="fixed">
      <parent link="base_link"/>
      <child link="left_front_pole"/>
      <origin xyz="0 0 0"/>
    </joint>

    <joint name="base_to_right_pole_one" type="fixed">
      <parent link="base_link"/>
      <child link="right_rear_pole"/>
      <origin xyz="0 0 0"/>
    </joint>

    <joint name="base_to_right_pole_two" type="fixed">
      <parent link="base_link"/>
      <child link="right_front_pole"/>
      <origin xyz="0 0 0"/>
    </joint>

    <joint name="base_to_perception_deck" type="fixed">
      <parent link="base_link"/>
      <child link="perception_deck"/>
      <origin xyz="0 0 0"/>
    </joint>

    <joint name="base_to_perception_deck_head" type="fixed">
      <parent link="base_link"/>
      <child link="perception_deck_head"/>
      <origin xyz="0 0 0"/>
    </joint>


</robot>
