<?xml version="1.0" ?>
 <robot name="allbot_4" xmlns:xacro="http://ros.org/wiki/xacro">
  <xacro:include filename="$(find allbot_urdf)/urdf/common_properties.xacro"/>
  <xacro:include filename="$(find allbot_urdf)/urdf/allbot.gazebo.xacro"/>
  <link name="base_footprint"/>

  <!-- allbot "base_link" -->
  <joint name="base_joint" type="fixed">
    <parent link="base_footprint"/>
    <child link="base_link"/>
    <origin xyz="0.0 0.0 0.010" rpy="0 0 0"/>
  </joint>

  <link name="base_link">
    <visual>
      <origin xyz="0 0 0.065" rpy="0 0 0"/>
      <geometry>
        <box size="0.23 0.15 0.005"/>
      </geometry>
      <material name="blue"/>
    </visual>

    <collision>
      <origin xyz="-0.032 0 0.070" rpy="0 0 0"/>
      <geometry>
        <box size="0.23 0.15 0.005"/>
      </geometry>
    </collision>

    <inertial>
      <origin xyz="0 0 0" rpy="0 0 0"/>
      <mass value="8.2573504e-01"/>
      <inertia ixx="2.2124416e-03" ixy="-1.2294101e-05" ixz="3.4938785e-05"
               iyy="2.1193702e-03" iyz="-5.0120904e-06"
               izz="2.0064271e-03" />
    </inertial>
  </link>

  <!-- allbot "base_link_head_joint" -->
  <joint name="base_link_head_joint" type="fixed">
    <parent link="base_link"/>
    <child link="base_link_head"/>
    <origin xyz="0.0 0.0 0.010" rpy="0 0 0"/>
  </joint>

  <link name="base_link_head">
    <visual>
      <origin xyz="0.11 0 0.055" rpy="0 0 0"/>
      <geometry>
        <cylinder length="0.005" radius="0.075"/>
      </geometry>
      <material name="blue"/>
    </visual>

    <collision>
      <origin xyz="-0.032 0 0.070" rpy="0 0 0"/>
      <geometry>
        <cylinder length="0.005" radius="0.075"/>
      </geometry>
    </collision>

    <inertial>
      <origin xyz="0 0 0" rpy="0 0 0"/>
      <mass value="8.2573504e-01"/>
      <inertia ixx="2.2124416e-03" ixy="-1.2294101e-05" ixz="3.4938785e-05"
               iyy="2.1193702e-03" iyz="-5.0120904e-06"
               izz="2.0064271e-03" />
    </inertial>
  </link>

  <!-- allbot "perception_deck" -->
  <joint name="perception_deck_joint" type="fixed">
    <parent link="base_link"/>
    <child link="perception_deck"/>
    <origin xyz="0.0 0.0 0.010" rpy="0 0 0"/>
  </joint>

  <link name="perception_deck">
    <visual>
      <origin xyz="0 0 0.105" rpy="0 0 0"/>
      <geometry>
        <box size="0.23 0.15 0.005"/>
      </geometry>
      <material name="blue"/>
    </visual>

    <collision>
      <origin xyz="-0.032 0 0.070" rpy="0 0 0"/>
      <geometry>
        <box size="0.23 0.15 0.005"/>
      </geometry>
    </collision>

    <inertial>
      <origin xyz="0 0 0" rpy="0 0 0"/>
      <mass value="8.2573504e-01"/>
      <inertia ixx="2.2124416e-03" ixy="-1.2294101e-05" ixz="3.4938785e-05"
               iyy="2.1193702e-03" iyz="-5.0120904e-06"
               izz="2.0064271e-03" />
    </inertial>
  </link>

  <!-- allbot "perception_deck_head" -->
  <joint name="perception_deck_head_joint" type="fixed">
    <parent link="base_link"/>
    <child link="perception_deck_head"/>
    <origin xyz="0.0 0.0 0.010" rpy="0 0 0"/>
  </joint>

  <link name="perception_deck_head">
    <visual>
      <origin xyz="0.11 0 0.105" rpy="0 0 0"/>
      <geometry>
        <cylinder length="0.005" radius="0.075"/>
      </geometry>
      <material name="blue"/>
    </visual>

    <collision>
      <origin xyz="-0.032 0 0.070" rpy="0 0 0"/>
      <geometry>
        <cylinder length="0.005" radius="0.075"/>
      </geometry>
    </collision>

    <inertial>
      <origin xyz="0 0 0" rpy="0 0 0"/>
      <mass value="8.2573504e-01"/>
      <inertia ixx="2.2124416e-03" ixy="-1.2294101e-05" ixz="3.4938785e-05"
               iyy="2.1193702e-03" iyz="-5.0120904e-06"
               izz="2.0064271e-03" />
    </inertial>
  </link>

  <!-- allbot "lidar_deck" -->
  <joint name="lidar_deck_joint" type="fixed">
    <parent link="base_link"/>
    <child link="lidar_deck"/>
    <origin xyz="0 0 0.010" rpy="0 0 0"/>
  </joint>

  <link name="lidar_deck">
    <visual>
      <origin xyz="0 0 0.155" rpy="0 0 0"/>
      <geometry>
        <box size="0.23 0.15 0.005"/>
      </geometry>
      <material name="blue"/>
    </visual>

    <collision>
      <origin xyz="-0.032 0 0.070" rpy="0 0 0"/>
      <geometry>
        <box size="0.23 0.15 0.005"/>
      </geometry>
    </collision>

    <inertial>
      <origin xyz="0 0 0" rpy="0 0 0"/>
      <mass value="8.2573504e-01"/>
      <inertia ixx="2.2124416e-03" ixy="-1.2294101e-05" ixz="3.4938785e-05"
               iyy="2.1193702e-03" iyz="-5.0120904e-06"
               izz="2.0064271e-03" />
    </inertial>
  </link>

  <!-- allbot "lidar_deck_head" -->
  <joint name="lidar_deck_head_joint" type="fixed">
    <parent link="base_link"/>
    <child link="lidar_deck_head"/>
    <origin xyz="0.0 0.0 0.010" rpy="0 0 0"/>
  </joint>

  <link name="lidar_deck_head">
    <visual>
      <origin xyz="0.11 0 0.155" rpy="0 0 0"/>
      <geometry>
        <cylinder length="0.005" radius="0.075"/>
      </geometry>        
      <material name="blue"/>
    </visual>

    <collision>
      <origin xyz="-0.032 0 0.070" rpy="0 0 0"/>
      <geometry>
        <cylinder length="0.005" radius="0.075"/>
      </geometry>
    </collision>

    <inertial>
      <origin xyz="0 0 0" rpy="0 0 0"/>
      <mass value="8.2573504e-01"/>
      <inertia ixx="2.2124416e-03" ixy="-1.2294101e-05" ixz="3.4938785e-05"
               iyy="2.1193702e-03" iyz="-5.0120904e-06"
               izz="2.0064271e-03" />
    </inertial>
  </link>

  <!-- allbot "lidar(base_scan)" -->
  <joint name="scan_joint" type="fixed">
    <parent link="base_link"/>
    <child link="base_scan"/>
    <origin xyz="0.0 0.0 0.010" rpy="0 0 0"/>
  </joint>

  <link name="base_scan">
    <visual>
      <origin xyz="0 0 0.200" rpy="0 0 0"/>
      <geometry>
        <mesh filename="package://allbot_urdf/urdf/meshes/lds.stl" scale="0.001 0.001 0.001"/>
      </geometry>
      <material name="dark"/>
    </visual>

    <collision>
      <origin xyz="0.015 0 -0.0065" rpy="0 0 0"/>
      <geometry>
        <cylinder length="0.0315" radius="0.055"/>
      </geometry>
    </collision>

    <inertial>
      <mass value="0.114" />
      <origin xyz="0 0 0" />
      <inertia ixx="0.001" ixy="0.0" ixz="0.0"
               iyy="0.001" iyz="0.0"
               izz="0.001" />
    </inertial>
  </link>

  <!-- allbot "wheel_rear_left" -->
  <joint name="wheel_rear_left_joint" type="continuous">
    <parent link="base_link"/>
    <child link="wheel_rear_left"/>
    <origin xyz="-0.08 0.08 0.023" rpy="-1.57 0 0"/>
    <axis xyz="0 0 1"/>
  </joint>

  <link name="wheel_rear_left">
    <visual>
      <origin xyz="0 0 0" rpy="1.57 0 0"/>
      <geometry>
        <mesh filename="package://allbot_urdf/urdf/meshes/left_tire.stl" scale="0.001 0.001 0.001"/>
      </geometry>
      <material name="dark"/>
    </visual>

    <collision>
      <origin xyz="0 0 0" rpy="0 0 0"/>
      <geometry>
        <cylinder length="0.018" radius="0.033"/>
      </geometry>
    </collision>

    <inertial>
      <origin xyz="0 0 0" />
      <mass value="2.8498940e-02" />
      <inertia ixx="1.1175580e-05" ixy="-4.2369783e-11" ixz="-5.9381719e-09"
               iyy="1.1192413e-05" iyz="-1.4400107e-11"
               izz="2.0712558e-05" />
      </inertial>
  </link>

  <!-- allbot "wheel_rear_right" -->
  <joint name="wheel_rear_right_joint" type="continuous">
    <parent link="base_link"/>
    <child link="wheel_rear_right"/>
    <origin xyz="-0.08 -0.08 0.023" rpy="-1.57 0 0"/>
    <axis xyz="0 0 1"/>
  </joint>

  <link name="wheel_rear_right">
    <visual>
      <origin xyz="0 0 0" rpy="1.57 0 0"/>
      <geometry>
        <mesh filename="package://allbot_urdf/urdf/meshes/right_tire.stl" scale="0.001 0.001 0.001"/>
      </geometry>
      <material name="dark"/>
    </visual>

    <collision>
      <origin xyz="0 0 0" rpy="0 0 0"/>
      <geometry>
        <cylinder length="0.018" radius="0.033"/>
      </geometry>
    </collision>

    <inertial>
      <origin xyz="0 0 0" />
      <mass value="2.8498940e-02" />
      <inertia ixx="1.1175580e-05" ixy="-4.2369783e-11" ixz="-5.9381719e-09"
               iyy="1.1192413e-05" iyz="-1.4400107e-11"
               izz="2.0712558e-05" />
      </inertial>
  </link>

  <!-- allbot "wheel_front_left" -->
  <joint name="wheel_front_left_joint" type="continuous">
    <parent link="base_link"/>
    <child link="wheel_front_left"/>
    <origin xyz="0.1 0.08 0.023" rpy="-1.57 0 0"/>
    <axis xyz="0 0 1"/>
  </joint>

  <link name="wheel_front_left">
    <visual>
      <origin xyz="0 0 0" rpy="1.57 0 0"/>
      <geometry>
        <mesh filename="package://allbot_urdf/urdf/meshes/left_tire.stl" scale="0.001 0.001 0.001"/>
      </geometry>
      <material name="dark"/>
    </visual>

    <collision>
      <origin xyz="0 0 0" rpy="0 0 0"/>
      <geometry>
        <cylinder length="0.018" radius="0.033"/>
      </geometry>
    </collision>

    <inertial>
      <origin xyz="0 0 0" />
      <mass value="2.8498940e-02" />
      <inertia ixx="1.1175580e-05" ixy="-4.2369783e-11" ixz="-5.9381719e-09"
               iyy="1.1192413e-05" iyz="-1.4400107e-11"
               izz="2.0712558e-05" />
      </inertial>
  </link>

  <!-- allbot "wheel_front_right" -->
  <joint name="wheel_front_right_joint" type="continuous">
    <parent link="base_link"/>
    <child link="wheel_front_right"/>
    <origin xyz="0.1 -0.08 0.023" rpy="-1.57 0 0"/>
    <axis xyz="0 0 1"/>
  </joint>

  <link name="wheel_front_right">
    <visual>
      <origin xyz="0 0 0" rpy="1.57 0 0"/>
      <geometry>
        <mesh filename="package://allbot_urdf/urdf/meshes/right_tire.stl" scale="0.001 0.001 0.001"/>
      </geometry>
      <material name="dark"/>
    </visual>

    <collision>
      <origin xyz="0 0 0" rpy="0 0 0"/>
      <geometry>
        <cylinder length="0.018" radius="0.033"/>
      </geometry>
    </collision>

    <inertial>
      <origin xyz="0 0 0" />
      <mass value="2.8498940e-02" />
      <inertia ixx="1.1175580e-05" ixy="-4.2369783e-11" ixz="-5.9381719e-09"
               iyy="1.1192413e-05" iyz="-1.4400107e-11"
               izz="2.0712558e-05" />
      </inertial>
  </link>

  <!-- allbot "left_rear_pole" -->
  <joint name="left_rear_pole_joint" type="fixed">
    <parent link="base_link"/>
    <child link="left_rear_pole"/>
    <origin xyz="0.0 0.0 0.010" rpy="0 0 0"/>
  </joint>

  <link name="left_rear_pole">
    <visual>
      <geometry>
        <box size="0.01 0.01 0.095"/>  
      </geometry>
      <origin rpy="0 0 0" xyz="-0.10 0.06 0.105"/> <!-- z should not under 0.105, z = 0.105 = 0.010 + 0.095 -->
      <material name="silver"/>
    </visual>
  </link>

  <!-- allbot "left_front_pole" -->
  <joint name="left_front_pole_joint" type="fixed">
    <parent link="base_link"/>
    <child link="left_front_pole"/>
    <origin xyz="0.0 0.0 0.010" rpy="0 0 0"/>
  </joint>

  <link name="left_front_pole">
    <visual>
      <geometry>
        <box size="0.01 0.01 0.095"/>  
      </geometry>
      <origin rpy="0 0 0" xyz="0.14 0.06 0.105"/> 
      <material name="silver"/>
    </visual>
  </link>

  <!-- allbot "right_rear_pole" -->
  <joint name="right_rear_pole_joint" type="fixed">
    <parent link="base_link"/>
    <child link="right_rear_pole"/>
    <origin xyz="0.0 0.0 0.010" rpy="0 0 0"/>
  </joint>

  <link name="right_rear_pole">
    <visual>
      <geometry>
        <box size="0.01 0.01 0.095"/>  
      </geometry>
      <origin rpy="0 0 0" xyz="-0.10 -0.06 0.105"/>
      <material name="silver"/>
    </visual>
  </link>

  <!-- allbot "right_front_pole" -->
  <joint name="right_front_pole_joint" type="fixed">
    <parent link="base_link"/>
    <child link="right_front_pole"/>
    <origin xyz="0.0 0.0 0.010" rpy="0 0 0"/>
  </joint>

  <link name="right_front_pole">
    <visual>
      <geometry>
        <box size="0.01 0.01 0.095"/>  
      </geometry>
      <origin rpy="0 0 0" xyz="0.14 -0.06 0.105"/>
      <material name="silver"/>
    </visual>
  </link>


  <!-- <joint name="imu_joint" type="fixed">
    <parent link="base_link"/>
    <child link="imu_link"/>
    <origin xyz="0.0 0.0 0.010" rpy="0 0 0"/>
  </joint>

  <link name="imu_link">
  <visual>
      <geometry>
        <box size="0.1 0.08 0.03"/>  
      </geometry>
      <origin rpy="0 0 0" xyz="0.07 0 0.07"/>
      <material name="green"/>
    </visual>
  </link> -->


</robot>
