<?xml version="1.0"?>
   <robot name="ALLAI-allbot">

    <link name="base_footprint"/>

    <link name="base_link">
      <visual>
        <geometry>
          <box size="0.23 0.15 0.005"/>
        </geometry>
        <origin rpy="0 0 0" xyz="0 0 0.065"/>
        <material name="blue">
          <color rgba="0 0 .8 1"/>
        </material>
      </visual>
    </link>

    <link name="base_controlbox">
      <visual>
        <geometry>
          <box size="0.13 0.09 0.035"/>
        </geometry>
        <origin rpy="0 0 0" xyz="0 0 0.085"/>
        <material name="green">
          <color rgba="0.0 0.8 0.0 1.0"/>
        </material>
      </visual>
    </link>

    <link name="base_link_head">
      <visual>
        <geometry>
          <cylinder length="0.005" radius="0.075"/>
        </geometry>
        <origin rpy="0 0 0" xyz="0.11 0 0.065"/>
        <material name="blue">
          <color rgba="0 0 .8 1"/>
        </material>
      </visual>
    </link>

    <link name="lidar_deck"> 
      <visual>
        <geometry>
          <box size="0.23 0.15 0.005"/>
        </geometry>
        <origin rpy="0 0 0" xyz="0 0 0.13"/>
        <material name="blue">
          <color rgba="0 0 .8 1"/>
        </material>
      </visual>
    </link>

    <link name="lidar_deck_head">
      <visual>
        <geometry>
          <cylinder length="0.005" radius="0.075"/>
        </geometry>
        <origin rpy="0 0 0" xyz="0.11 0 0.13"/>
        <material name="blue">
          <color rgba="0 0 .8 1"/>
        </material>
      </visual>
    </link>

    <link name="wheel_rear_left">
      <visual>
        <geometry>
          <cylinder length="0.027" radius="0.0345"/>
        </geometry>
        <origin rpy="0 0 0" xyz="0 0 0"/>        
        <material name="black">
          <color rgba="0 0 0 1"/>
        </material>
      </visual>
    </link>

    <link name="wheel_rear_right">
      <visual>
        <geometry>
          <cylinder length="0.027" radius="0.0345"/>
        </geometry>
        <origin rpy="0 0 0" xyz="0 0 0"/>
        <material name="black">
          <color rgba="0 0 0 1"/>
        </material>
      </visual>
    </link>

    <link name="wheel_front_right">
      <visual>
        <geometry>
          <cylinder length="0.027" radius="0.0345"/>
        </geometry>
        <origin rpy="0 0 0" xyz="0 0 0"/>
        <material name="black">
          <color rgba="0 0 0 1"/>
        </material>
      </visual>
    </link>

    <link name="wheel_front_left">
      <visual>
        <geometry>
          <cylinder length="0.027" radius="0.0345"/>
        </geometry>
        <origin rpy="0 0 0" xyz="0 0 0"/>
        <material name="black">
          <color rgba="0 0 0 1"/>
        </material>
      </visual>
    </link>

    <link name="wheel_rear_track">
      <visual>
        <geometry>
          <box size="0.04 0.19 0.002"/>
        </geometry>
        <origin rpy="0 0 0" xyz="-0.085 0.0 0.06"/>
        <material name="white"/>
      </visual>
    </link>

    <link name="wheel_front_track">
      <visual>
        <geometry>
          <box size="0.04 0.19 0.002"/>
        </geometry>
        <origin rpy="0 0 0" xyz="0.10 0.0 0.06"/>
        <material name="white"/>
      </visual>
    </link>

    <link name="laser">
      <visual>
        <geometry>
          <cylinder length="0.04" radius="0.04"/>
        </geometry>
        <origin rpy="0 0 0" xyz="0.06 0 0.15"/>
        <material name="black"/>
      </visual>
    </link>
    
    <link name="left_rear_pole">
      <visual>
        <geometry>
          <box size="0.01 0.01 0.065"/>
        </geometry>
        <origin rpy="0 0 0" xyz="-0.10 0.055 0.096"/>
        <material name="silver">
          <color rgba="192 192 192 0.6"/>
        </material>
      </visual>
    </link>

    <link name="left_front_pole">
      <visual>
        <geometry>
          <box size="0.01 0.01 0.065"/>
        </geometry>
        <origin rpy="0 0 0" xyz="0.13 0.055 0.096"/>
        <material name="silver">
          <color rgba="192 192 192 0.6"/>
        </material>
      </visual>
    </link>

    <link name="right_rear_pole">
      <visual>
        <geometry>
          <box size="0.01 0.01 0.065"/>
        </geometry>
        <origin rpy="0 0 0" xyz="-0.10 -0.055 0.096"/>
        <material name="silver">
          <color rgba="192 192 192 0.6"/>
        </material>
      </visual>
    </link>

    <link name="right_front_pole">
      <visual>
        <geometry>
          <box size="0.01 0.01 0.065"/>
        </geometry>
        <origin rpy="0 0 0" xyz="0.13 -0.055 0.096"/>
        <material name="silver">
          <color rgba="192 192 192 0.6"/>
        </material>
      </visual>
    </link>

    <joint name="base_joint" type="fixed">
      <parent link="base_footprint"/>
      <child link="base_link"/>
      <origin xyz="0.0 0.0 0.0" rpy="0 0 0"/>
    </joint>

    <joint name="base_to_link_head" type="fixed">
      <parent link="base_link"/>
      <child link="base_link_head"/>
      <origin xyz="0.0 0.0 0.0" rpy="0 0 0"/>
    </joint>

    <joint name="base_to_controlbox" type="fixed">
      <parent link="base_link"/>
      <child link="base_controlbox"/>
      <origin xyz="0.0 0.0 0.0" rpy="0 0 0"/>
    </joint>
 
    <joint name="base_to_lidar_deck" type="fixed">
      <parent link="base_link"/>
      <child link="lidar_deck"/>
      <origin xyz="0.0 0.0 0.0" rpy="0 0 0"/>
    </joint>

    <joint name="base_to_lidar_deck_head" type="fixed">
      <parent link="base_link"/>
      <child link="lidar_deck_head"/>
      <origin xyz="0.0 0.0 0.0" rpy="0 0 0"/>
    </joint>

    <joint name="base_to_wheel_rear_track" type="fixed">
      <parent link="base_link"/>
      <child link="wheel_rear_track"/>
      <origin xyz="0.0 0.0 0.0" rpy="0 0 0"/>
    </joint>

    <joint name="base_to_wheel_front_track" type="fixed">
      <parent link="base_link"/>
      <child link="wheel_front_track"/>
      <origin xyz="0.0 0.0 0.0" rpy="0 0 0"/>
    </joint>


    <joint name="base_to_wheel_front_right" type="continuous">
      <parent link="base_link"/>
      <child link="wheel_front_right"/> 
      <origin rpy="1.57 0 0" xyz="0.10 -0.11 0.0345"/>
    </joint>

    <joint name="base_to_wheel_front_left" type="continuous">
      <parent link="base_link"/>
      <child link="wheel_front_left"/>
      <origin rpy="1.57 0 0" xyz="0.10 0.11 0.0345"/>
    </joint>

    <joint name="base_to_wheel_rear_left" type="continuous">
      <parent link="base_link"/>
      <child link="wheel_rear_left"/>
      <origin rpy="1.57 0 0" xyz="-0.085 0.11 0.0345"/>
    </joint>

    <joint name="base_to_wheel_rear_right" type="continuous">
      <parent link="base_link"/>
      <child link="wheel_rear_right"/>
      <origin rpy="1.57 0 0" xyz="-0.085 -0.11 0.0345"/>
    </joint>

    <joint name="base_to_laser" type="fixed">
      <parent link="base_link"/>
      <child link="laser"/>
      <origin xyz="0.0 0.0 0.0"/>      
    </joint>

    <joint name="base_to_left_pole_one" type="fixed">
      <parent link="base_link"/>
      <child link="left_rear_pole"/>
      <origin xyz="0 0 0"/>
    </joint>

    <joint name="base_to_left_pole_two" type="fixed">
      <parent link="base_link"/>
      <child link="left_front_pole"/>
      <origin xyz="0 0 0"/>
    </joint>

    <joint name="base_to_right_pole_one" type="fixed">
      <parent link="base_link"/>
      <child link="right_rear_pole"/>
      <origin xyz="0 0 0"/>
    </joint>

    <joint name="base_to_right_pole_two" type="fixed">
      <parent link="base_link"/>
      <child link="right_front_pole"/>
      <origin xyz="0 0 0"/>
    </joint>

</robot>
